<?xml version="1.0" encoding="utf-8" ?>
<!-- =================================================================================== -->
<!-- |    This document was autogenerated by xacro from /home/ubuntu/catkin_ws/src/wormy_arm/wormy_arm_description/urdf/wormy_arm_onbox.xacro | -->
<!-- |    EDITING THIS FILE BY HAND IS NOT RECOMMENDED                                 | -->
<!-- =================================================================================== -->
<robot name="wormy_arm_robot">
    <!-- wormy_arm -->
    <link name="base_link" />
    <link name="wormy_arm_base_link" />
    <joint name="wormy_arm_base_link_to_base" type="fixed">
        <parent link="wormy_arm_base_link" />
        <child link="wormy_arm_case" />
        <origin rpy="0.0 0 0" xyz="0 0 0" />
    </joint>
    <link name="wormy_arm_case">
        <visual>
            <origin rpy="0 -0 0" xyz="0 0 0" />
            <geometry>
                <mesh filename="package://wormy_arm_description/urdf/raw/joint_0_visual.stl" />
            </geometry>
            <material name="joint_0_material">
                <color rgba="0.817881 0.836208 0.852695 1.0" />
            </material>
        </visual>
        <collision>
            <origin rpy="0 -0 0" xyz="0 0 0" />
            <geometry>
                <mesh filename="package://wormy_arm_description/urdf/raw/joint_0_collision.stl" />
            </geometry>
            <material name="joint_0_material">
                <color rgba="0.5 0.5 0.5 1.0" />
            </material>
        </collision>
        
<inertial>
            <origin rpy="0 0 0" xyz="0.0059763 0.0125469 0.0329924" />
            <mass value="0.329343" />
            <inertia ixx="0.000437093" ixy="-2.32247e-05" ixz="4.16777e-05" iyy="0.000408938" iyz="-9.64991e-06" izz="0.000369942" />
        </inertial>

    </link>
    <link name="wormy_arm_link_1">
        <visual>
            <origin rpy="0 -0 0" xyz="0 0 0" />
            <geometry>
                <mesh filename="package://wormy_arm_description/urdf/raw/joint_1_visual.stl" />
            </geometry>
            <material name="joint_1_material">
                <color rgba="0.799704 0.80046 0.803592 1.0" />
            </material>
        </visual>
        <collision>
            <origin rpy="0 -0 0" xyz="0 0 0" />
            <geometry>
                <mesh filename="package://wormy_arm_description/urdf/raw/joint_1_collision.stl" />
            </geometry>
            <material name="joint_1_material">
                <color rgba="0.5 0.5 0.5 1.0" />
            </material>
        </collision>
        
<inertial>
            <origin rpy="0 0 0" xyz="1.21246e-05 -0.00651843 -0.0502915" />
            <mass value="0.192291" />
            <inertia ixx="0.000177516" ixy="1.6057e-08" ixz="7.72555e-09" iyy="0.000164493" iyz="-3.22981e-05" izz="0.000113033" />
        </inertial>

    </link>
    <link name="wormy_arm_link_2">
        <visual>
            <origin rpy="0 -0 0" xyz="0 0 0" />
            <geometry>
                <mesh filename="package://wormy_arm_description/urdf/raw/joint_2_visual.stl" />
            </geometry>
            <material name="joint_2_material">
                <color rgba="0.853971 0.854912 0.858811 1.0" />
            </material>
        </visual>
        <collision>
            <origin rpy="0 -0 0" xyz="0 0 0" />
            <geometry>
                <mesh filename="package://wormy_arm_description/urdf/raw/joint_2_collision.stl" />
            </geometry>
            <material name="joint_2_material">
                <color rgba="0.5 0.5 0.5 1.0" />
            </material>
        </collision>
        
<inertial>
            <origin rpy="0 0 0" xyz="2.09617e-05 -0.0657069 -0.0594829" />
            <mass value="0.370781" />
            <inertia ixx="0.00124541" ixy="7.56741e-08" ixz="-2.32197e-08" iyy="0.000331076" iyz="-0.000163069" izz="0.00114896" />
        </inertial>

    </link>
    <link name="wormy_arm_link_3">
        <visual>
            <origin rpy="0 -0 0" xyz="0 0 0" />
            <geometry>
                <mesh filename="package://wormy_arm_description/urdf/raw/joint_3_visual.stl" />
            </geometry>
            <material name="joint_3_material">
                <color rgba="0.844127 0.845213 0.849714 1.0" />
            </material>
        </visual>
        <collision>
            <origin rpy="0 -0 0" xyz="0 0 0" />
            <geometry>
                <mesh filename="package://wormy_arm_description/urdf/raw/joint_3_collision.stl" />
            </geometry>
            <material name="joint_3_material">
                <color rgba="0.5 0.5 0.5 1.0" />
            </material>
        </collision>
        
<inertial>
            <origin rpy="0 0 0" xyz="1.5072e-05 -0.0502234 -0.0574874" />
            <mass value="0.321132" />
            <inertia ixx="0.00078854" ixy="5.93035e-08" ixz="-7.35249e-10" iyy="0.000288245" iyz="-0.000126739" izz="0.000700904" />
        </inertial>

    </link>
    <link name="wormy_arm_link_4">
        <visual>
            <origin rpy="0 -0 0" xyz="0 0 0" />
            <geometry>
                <mesh filename="package://wormy_arm_description/urdf/raw/joint_4_visual.stl" />
            </geometry>
            <material name="joint_4_material">
                <color rgba="0.799704 0.80046 0.803592 1.0" />
            </material>
        </visual>
        <collision>
            <origin rpy="0 -0 0" xyz="0 0 0" />
            <geometry>
                <mesh filename="package://wormy_arm_description/urdf/raw/joint_4_collision.stl" />
            </geometry>
            <material name="joint_4_material">
                <color rgba="0.5 0.5 0.5 1.0" />
            </material>
        </collision>
        
<inertial>
            <origin rpy="0 0 0" xyz="1.21246e-05 -0.00651843 -0.0502915" />
            <mass value="0.192291" />
            <inertia ixx="0.000177516" ixy="1.6057e-08" ixz="7.72555e-09" iyy="0.000164493" iyz="-3.22981e-05" izz="0.000113033" />
        </inertial>

    </link>
    <link name="wormy_arm_link_5">
        <visual>
            <origin rpy="0 -0 0" xyz="0 0 0" />
            <geometry>
                <mesh filename="package://wormy_arm_description/urdf/raw/joint_5_visual.stl" />
            </geometry>
            <material name="joint_5_material">
                <color rgba="0.799704 0.80046 0.803592 1.0" />
            </material>
        </visual>
        <collision>
            <origin rpy="0 -0 0" xyz="0 0 0" />
            <geometry>
                <mesh filename="package://wormy_arm_description/urdf/raw/joint_5_collision.stl" />
            </geometry>
            <material name="joint_5_material">
                <color rgba="0.5 0.5 0.5 1.0" />
            </material>
        </collision>
        
<inertial>
            <origin rpy="0 0 0" xyz="1.21246e-05 -0.00691252 -0.0502915" />
            <mass value="0.192291" />
            <inertia ixx="0.000178174" ixy="1.63035e-08" ixz="7.72555e-09" iyy="0.000164493" iyz="-3.29513e-05" izz="0.00011369" />
        </inertial>

    </link>
    <link name="wormy_arm_ee">
        <visual>
            <origin rpy="0 -0 0" xyz="0 0 0" />
            <geometry>
                <mesh filename="package://wormy_arm_description/urdf/raw/joint_connector_a2_visual.stl" />
            </geometry>
            <material name="joint_connector_a2_material">
                <color rgba="0.917647 0.917647 0.917647 1.0" />
            </material>
        </visual>
        <collision>
            <origin rpy="0 -0 0" xyz="0 0 0" />
            <geometry>
                <mesh filename="package://wormy_arm_description/urdf/raw/joint_connector_a2_collision.stl" />
            </geometry>
            <material name="joint_connector_a2_material">
                <color rgba="0.5 0.5 0.5 1.0" />
            </material>
        </collision>
        
<inertial>
            <origin rpy="0 0 0" xyz="1.14754e-18 5.6599e-06 -0.0118831" />
            <mass value="0.0234539" />
            <inertia ixx="5.31243e-06" ixy="-2.09537e-36" ixz="-2.05025e-10" iyy="5.31245e-06" iyz="2.85876e-10" izz="9.79132e-06" />
        </inertial>

    </link>
    <joint name="wormy_arm_joint_5" type="revolute">
        <origin rpy="-1.5708 -1.5708 0" xyz="-2.77556e-17 -0.02937 -0.074" />
        <parent link="wormy_arm_link_5" />
        <child link="wormy_arm_ee" />
        <axis xyz="0 0 1" />
        <limit effort="1.5" lower="-3.14" upper="3.14" velocity="3.14" />
        <joint_properties friction="0.0" />
    </joint>
    <joint name="wormy_arm_joint_4" type="revolute">
        <origin rpy="-1.5708 1.5708 0" xyz="-7.49184e-17 -0.02887 -0.074" />
        <parent link="wormy_arm_link_4" />
        <child link="wormy_arm_link_5" />
        <axis xyz="0 0 1" />
        <limit effort="1.5" lower="-3.14" upper="3.14" velocity="3.14" />
        <joint_properties friction="0.0" />
    </joint>
    <joint name="wormy_arm_joint_3" type="revolute">
        <origin rpy="3.14159 -1.43376e-15 -3.14159" xyz="-1.97569e-16 -0.10387 -0.04483" />
        <parent link="wormy_arm_link_3" />
        <child link="wormy_arm_link_4" />
        <axis xyz="0 0 1" />
        <limit effort="1.5" lower="-3.14" upper="3.14" velocity="3.14" />
        <joint_properties friction="0.0" />
    </joint>
    <joint name="wormy_arm_joint_2" type="revolute">
        <origin rpy="-3.14159 -2.16934e-16 3.14159" xyz="5.37764e-17 -0.13387 -0.04463" />
        <parent link="wormy_arm_link_2" />
        <child link="wormy_arm_link_3" />
        <axis xyz="0 0 1" />
        <limit effort="1.5" lower="-3.14" upper="3.14" velocity="3.14" />
        <joint_properties friction="0.0" />
    </joint>
    <joint name="wormy_arm_joint_1" type="revolute">
        <origin rpy="1.5708 -1.0842e-19 3.14159" xyz="2.36085e-16 -0.02887 -0.074" />
        <parent link="wormy_arm_link_1" />
        <child link="wormy_arm_link_2" />
        <axis xyz="0 0 1" />
        <limit effort="1.5" lower="-3.14" upper="3.14" velocity="3.14" />
        <joint_properties friction="0.0" />
    </joint>
    <joint name="wormy_arm_joint_0" type="revolute">
        <origin rpy="-3.14159 -4.31408e-32 -3.14159" xyz="-0.00020294 0.000945844 0.08702" />
        <parent link="wormy_arm_case" />
        <child link="wormy_arm_link_1" />
        <axis xyz="0 0 1" />
        <limit effort="1.5" lower="-3.14" upper="3.14" velocity="3.14" />
        <joint_properties friction="0.0" />
    </joint>
    <link name="box_link">
        <visual>
            <origin rpy="0 0 0" xyz="0 0 0" />
            <geometry>
                <box size="1 1 0.5" />
            </geometry>
            <material name="black">
                <color rgba="0.1 0.1 0.1 2.0" />
            </material>
        </visual>
    </link>
    <joint name="base2box_joint" type="fixed">
        <parent link="base_link" />
        <child link="box_link" />
        <origin rpy="0.0 0 0" xyz="0 0 0.25" />
    </joint>
    <joint name="box2arm_joint" type="fixed">
        <parent link="box_link" />
        <child link="wormy_arm_base_link" />
        <origin rpy="0.0 0 0" xyz="0 0 0.25" />
    </joint>
    
<transmission name="trans_wormy_arm_joint_5">
        <type>transmission_interface/SimpleTransmission</type>
        <joint name="wormy_arm_joint_5">
            <hardwareInterface>hardware_interface/EffortJointInterface</hardwareInterface>
        </joint>
        <actuator name="wormy_arm_joint_5_motor">
            <hardwareInterface>hardware_interface/EffortJointInterface</hardwareInterface>
            <mechanicalReduction>1</mechanicalReduction>
        </actuator>
    </transmission>
    <transmission name="trans_wormy_arm_joint_4">
        <type>transmission_interface/SimpleTransmission</type>
        <joint name="wormy_arm_joint_4">
            <hardwareInterface>hardware_interface/EffortJointInterface</hardwareInterface>
        </joint>
        <actuator name="wormy_arm_joint_4_motor">
            <hardwareInterface>hardware_interface/EffortJointInterface</hardwareInterface>
            <mechanicalReduction>1</mechanicalReduction>
        </actuator>
    </transmission>
    <transmission name="trans_wormy_arm_joint_3">
        <type>transmission_interface/SimpleTransmission</type>
        <joint name="wormy_arm_joint_3">
            <hardwareInterface>hardware_interface/EffortJointInterface</hardwareInterface>
        </joint>
        <actuator name="wormy_arm_joint_3_motor">
            <hardwareInterface>hardware_interface/EffortJointInterface</hardwareInterface>
            <mechanicalReduction>1</mechanicalReduction>
        </actuator>
    </transmission>
    <transmission name="trans_wormy_arm_joint_2">
        <type>transmission_interface/SimpleTransmission</type>
        <joint name="wormy_arm_joint_2">
            <hardwareInterface>hardware_interface/EffortJointInterface</hardwareInterface>
        </joint>
        <actuator name="wormy_arm_joint_2_motor">
            <hardwareInterface>hardware_interface/EffortJointInterface</hardwareInterface>
            <mechanicalReduction>1</mechanicalReduction>
        </actuator>
    </transmission>
    <transmission name="trans_wormy_arm_joint_1">
        <type>transmission_interface/SimpleTransmission</type>
        <joint name="wormy_arm_joint_1">
            <hardwareInterface>hardware_interface/EffortJointInterface</hardwareInterface>
        </joint>
        <actuator name="wormy_arm_joint_1_motor">
            <hardwareInterface>hardware_interface/EffortJointInterface</hardwareInterface>
            <mechanicalReduction>1</mechanicalReduction>
        </actuator>
    </transmission>
    <transmission name="trans_wormy_arm_joint_0">
        <type>transmission_interface/SimpleTransmission</type>
        <joint name="wormy_arm_joint_0">
            <hardwareInterface>hardware_interface/EffortJointInterface</hardwareInterface>
        </joint>
        <actuator name="wormy_arm_joint_0_motor">
            <hardwareInterface>hardware_interface/EffortJointInterface</hardwareInterface>
            <mechanicalReduction>1</mechanicalReduction>
        </actuator>
    </transmission>
    <gazebo>
        <plugin name="gazebo_ros_control" filename="libgazebo_ros_control.so">
            <robotNamespace>/</robotNamespace>
        </plugin>
    </gazebo>
</robot>